Workbook

Sheet Assumptions
A1: Rates Workbench – business model assumptions
A2: Blue = editable input; yellow = key lever. All $ in $M. Figures are illustrative judgment, not market data.
A4: Scalar inputs | C4: Value
A5: Scenario (1=Downside, 2=Base, 3=Upside) | C5: 2
A6: Volume multiplier – Downside | C6: 0.5
A7: Volume multiplier – Base | C7: 1
A8: Volume multiplier – Upside | C8: 1.4
A9: Active volume multiplier | C9: =INDEX(C6:C8,C5) -> 1
A10: Direct pricing
A11: License – Large tier ($50–250B), $M | C11: 0.8
A12: License – Mid tier ($10–50B), $M | C12: 0.35
A13: License – design partner, $M | C13: 0.25
A14: Share of license paid in year of sale | C14: 0.8
A15: Onboarding + validation support – Large, $M | C15: 0.25
A16: Onboarding + validation support – Mid, $M | C16: 0.15
A17: Onboarding + validation support – design partner, $M | C17: 0.15
A18: Update subscription, % of license per year | C18: 0.2
A19: Design-partner subscription, $M/yr | C19: 0.15
A20: Ongoing customization – Large, $M/yr | C20: 0.15
A21: Ongoing customization – Mid, $M/yr | C21: 0.075
A22: Ongoing customization – design partner, $M/yr | C22: 0.15
A23: Delivery effort
A24: FDE-years per new Large bank | C24: 0.3
A25: FDE-years per new Mid bank | C25: 0.25
A26: FDE-years per new design partner | C26: 0.5
A27: FDE per existing Large/design-partner bank | C27: 0.25
A28: FDE per existing Mid bank | C28: 0.15
A29: Minimum FDE headcount | C29: 1.5
A30: Channel pricing
A31: Outsourced-ALM partner platform fee, $M/yr | C31: 0.35
A32: Royalty per partner-served institution, $M/yr | C32: 0.008
A33: Validation-firm challenger license, $M/yr | C33: 0.15
A34: M&A / purchase-accounting engagement fee, $M | C34: 0.1
A35: Advisory (Big 4) enterprise license, $M/yr | C35: 0.5
A36: Costs
A37: Fully loaded cost per head, $M/yr | C37: 0.275
A38: Commission on direct license bookings | C38: 0.1
A39: Commission on channel revenue | C39: 0.05
A40: Market pools
A41: Pool: US regional banks $10–250B (count) | C41: 150
...

Sheet Model
A1: Projections ($M unless noted) – scenario-driven
A2: ="Active scenario: "&INDEX({"Downside","Base","Upside"},Assumptions!$C$5) -> Active scenario: Base
C4: Y1 | D4: Y2 | E4: Y3 | F4: Y4 | G4: Y5
A5: Direct banks
A6: New design partners | C6: =Assumptions!C47 -> 2 | D6: =Assumptions!D47 -> 0 | E6: =Assumptions!E47 -> 0 | F6: =Assumptions!F47 -> 0 | G6: =Assumptions!G47 -> 0
A7: New Large-tier banks | C7: =Assumptions!C48*Assumptions!$C$9 -> 0 | D7: =Assumptions!D48*Assumptions!$C$9 -> 1 | E7: =Assumptions!E48*Assumptions!$C$9 -> 2 | F7: =Assumptions!F48*Assumptions!$C$9 -> 1 | G7: =Assumptions!G48*Assumptions!$C$9 -> 2
A8: New Mid-tier banks | C8: =Assumptions!C49*Assumptions!$C$9 -> 0 | D8: =Assumptions!D49*Assumptions!$C$9 -> 1 | E8: =Assumptions!E49*Assumptions!$C$9 -> 1 | F8: =Assumptions!F49*Assumptions!$C$9 -> 2 | G8: =Assumptions!G49*Assumptions!$C$9 -> 2
A9: Cumulative design partners | C9: =C6 -> 2 | D9: =C9+D6 -> 2 | E9: =D9+E6 -> 2 | F9: =E9+F6 -> 2 | G9: =F9+G6 -> 2
A10: Cumulative Large | C10: =C7 -> 0 | D10: =C10+D7 -> 1 | E10: =D10+E7 -> 3 | F10: =E10+F7 -> 4 | G10: =F10+G7 -> 6
A11: Cumulative Mid | C11: =C8 -> 0 | D11: =C11+D8 -> 1 | E11: =D11+E8 -> 2 | F11: =E11+F8 -> 4 | G11: =F11+G8 -> 6
A12: Cumulative direct banks | C12: =C9+C10+C11 -> 2 | D12: =D9+D10+D11 -> 4 | E12: =E9+E10+E11 -> 7 | F12: =F9+F10+F11 -> 10 | G12: =G9+G10+G11 -> 14
A13: Penetration of regional pool | C13: =IFERROR(C12/Assumptions!$C$41,0) -> 0.013333333 | D13: =IFERROR(D12/Assumptions!$C$41,0) -> 0.026666667 | E13: =IFERROR(E12/Assumptions!$C$41,0) -> 0.046666667 | F13: =IFERROR(F12/Assumptions!$C$41,0) -> 0.066666667 | G13: =IFERROR(G12/Assumptions!$C$41,0) -> 0.093333333
A14: Revenue
A15: License bookings | C15: =C6*Assumptions!$C$13+C7*Assumptions!$C$11+C8*Assumptions!$C$12 -> 0.5 | D15: =D6*Assumptions!$C$13+D7*Assumptions!$C$11+D8*Assumptions!$C$12 -> 1.15 | E15: =E6*Assumptions!$C$13+E7*Assumptions!$C$11+E8*Assumptions!$C$12 -> 1.95 | F15: =F6*Assumptions!$C$13+F7*Assumptions!$C$11+F8*Assumptions!$C$12 -> 1.5 | G15: =G6*Assumptions!$C$13+G7*Assumptions!$C$11+G8*Assumptions!$C$12 -> 2.3
A16: License revenue (cash timing) | C16: =Assumptions!$C$14*C15 -> 0.4 | D16: =Assumptions!$C$14*D15+(1-Assumptions!$C$14)*C15 -> 1.02 | E16: =Assumptions!$C$14*E15+(1-Assumptions!$C$14)*D15 -> 1.79 | F16: =Assumptions!$C$14*F15+(1-Assumptions!$C$14)*E15 -> 1.59 | G16: =Assumptions!$C$14*G15+(1-Assumptions!$C$14)*F15 -> 2.14
A17: Onboarding + validation support | C17: =C6*Assumptions!$C$17+C7*Assumptions!$C$15+C8*Assumptions!$C$16 -> 0.3 | D17: =D6*Assumptions!$C$17+D7*Assumptions!$C$15+D8*Assumptions!$C$16 -> 0.4 | E17: =E6*Assumptions!$C$17+E7*Assumptions!$C$15+E8*Assumptions!$C$16 -> 0.65 | F17: =F6*Assumptions!$C$17+F7*Assumptions!$C$15+F8*Assumptions!$C$16 -> 0.55 | G17: =G6*Assumptions!$C$17+G7*Assumptions!$C$15+G8*Assumptions!$C$16 -> 0.8
A18: Update subscription | C18: =0 -> 0 | D18: =C9*Assumptions!$C$19+C10*Assumptions!$C$11*Assumptions!$C$18+C11*Assumptions!$C$12*Assumptions!$C$18 -> 0.3 | E18: =D9*Assumptions!$C$19+D10*Assumptions!$C$11*Assumptions!$C$18+D11*Assumptions!$C$12*Assumptions!$C$18 -> 0.53 | F18: =E9*Assumptions!$C$19+E10*Assumptions!$C$11*Assumptions!$C$18+E11*Assumptions!$C$12*Assumptions!$C$18 -> 0.92 | G18: =F9*Assumptions!$C$19+F10*Assumptions!$C$11*Assumptions!$C$18+F11*Assumptions!$C$12*Assumptions!$C$18 -> 1.22
A19: Ongoing customization services | C19: =0 -> 0 | D19: =C9*Assumptions!$C$22+C10*Assumptions!$C$20+C11*Assumptions!$C$21 -> 0.3 | E19: =D9*Assumptions!$C$22+D10*Assumptions!$C$20+D11*Assumptions!$C$21 -> 0.525 | F19: =E9*Assumptions!$C$22+E10*Assumptions!$C$20+E11*Assumptions!$C$21 -> 0.9 | G19: =F9*Assumptions!$C$22+F10*Assumptions!$C$20+F11*Assumptions!$C$21 -> 1.2
A20: Direct revenue | C20: =SUM(C16:C19) -> 0.7 | D20: =SUM(D16:D19) -> 2.02 | E20: =SUM(E16:E19) -> 3.495 | F20: =SUM(F16:F19) -> 3.96 | G20: =SUM(G16:G19) -> 5.36
A21: ALM partner platform fees | C21: =Assumptions!C50*Assumptions!$C$9*Assumptions!$C$31 -> 0 | D21: =Assumptions!D50*Assumptions!$C$9*Assumptions!$C$31 -> 0 | E21: =Assumptions!E50*Assumptions!$C$9*Assumptions!$C$31 -> 0.35 | F21: =Assumptions!F50*Assumptions!$C$9*Assumptions!$C$31 -> 0.7 | G21: =Assumptions!G50*Assumptions!$C$9*Assumptions!$C$31 -> 1.05
A22: Partner per-institution royalties | C22: =Assumptions!C51*Assumptions!$C$9*Assumptions!$C$32 -> 0 | D22: =Assumptions!D51*Assumptions!$C$9*Assumptions!$C$32 -> 0 | E22: =Assumptions!E51*Assumptions!$C$9*Assumptions!$C$32 -> 0.32 | F22: =Assumptions!F51*Assumptions!$C$9*Assumptions!$C$32 -> 1.2 | G22: =Assumptions!G51*Assumptions!$C$9*Assumptions!$C$32 -> 3.2
A23: Validation-firm licenses | C23: =Assumptions!C52*Assumptions!$C$9*Assumptions!$C$33 -> 0 | D23: =Assumptions!D52*Assumptions!$C$9*Assumptions!$C$33 -> 0.15 | E23: =Assumptions!E52*Assumptions!$C$9*Assumptions!$C$33 -> 0.3 | F23: =Assumptions!F52*Assumptions!$C$9*Assumptions!$C$33 -> 0.6 | G23: =Assumptions!G52*Assumptions!$C$9*Assumptions!$C$33 -> 0.75
A24: M&A engagements | C24: =Assumptions!C53*Assumptions!$C$9*Assumptions!$C$34 -> 0 | D24: =Assumptions!D53*Assumptions!$C$9*Assumptions!$C$34 -> 0.2 | E24: =Assumptions!E53*Assumptions!$C$9*Assumptions!$C$34 -> 0.6 | F24: =Assumptions!F53*Assumptions!$C$9*Assumptions!$C$34 -> 1.2 | G24: =Assumptions!G53*Assumptions!$C$9*Assumptions!$C$34 -> 2
A25: Advisory enterprise licenses | C25: =Assumptions!C54*Assumptions!$C$9*Assumptions!$C$35 -> 0 | D25: =Assumptions!D54*Assumptions!$C$9*Assumptions!$C$35 -> 0 | E25: =Assumptions!E54*Assumptions!$C$9*Assumptions!$C$35 -> 0 | F25: =Assumptions!F54*Assumptions!$C$9*Assumptions!$C$35 -> 0.5 | G25: =Assumptions!G54*Assumptions!$C$9*Assumptions!$C$35 -> 1
A26: Channel revenue | C26: =SUM(C21:C25) -> 0 | D26: =SUM(D21:D25) -> 0.35 | E26: =SUM(E21:E25) -> 1.57 | F26: =SUM(F21:F25) -> 4.2 | G26: =SUM(G21:G25) -> 8
A27: Total revenue | C27: =C20+C26 -> 0.7 | D27: =D20+D26 -> 2.37 | E27: =E20+E26 -> 5.065 | F27: =F20+F26 -> 8.16 | G27: =G20+G26 -> 13.36
A28: Recurring revenue (subscription + annual channel licenses) | C28: =C18+C21+C22+C23+C25 -> 0 | D28: =D18+D21+D22+D23+D25 -> 0.45 | E28: =E18+E21+E22+E23+E25 -> 1.5 | F28: =F18+F21+F22+F23+F25 -> 3.92 | G28: =G18+G21+G22+G23+G25 -> 7.22
A29: Recurring share | C29: =IFERROR(C28/C27,0) -> 0 | D29: =IFERROR(D28/D27,0) -> 0.18987342 | E29: =IFERROR(E28/E27,0) -> 0.29615005 | F29: =IFERROR(F28/F27,0) -> 0.48039216 | G29: =IFERROR(G28/G27,0) -> 0.54041916
A30: Channel share | C30: =IFERROR(C26/C27,0) -> 0 | D30: =IFERROR(D26/D27,0) -> 0.14767932 | E30: =IFERROR(E26/E27,0) -> 0.30997038 | F30: =IFERROR(F26/F27,0) -> 0.51470588 | G30: =IFERROR(G26/G27,0) -> 0.5988024
A31: Channel penetration of community pool | C31: =IFERROR(Assumptions!C51*Assumptions!$C$9/Assumptions!$C$42,0) -> 0 | D31: =IFERROR(Assumptions!D51*Assumptions!$C$9/Assumptions!$C$42,0) -> 0 | E31: =IFERROR(Assumptions!E51*Assumptions!$C$9/Assumptions!$C$42,0) -> 0.0047058824 | F31: =IFERROR(Assumptions!F51*Assumptions!$C$9/Assumptions!$C$42,0) -> 0.017647059 | G31: =IFERROR(Assumptions!G51*Assumptions!$C$9/Assumptions!$C$42,0) -> 0.047058824
A32: Headcount
A33: FDEs | C33: =MAX(Assumptions!$C$29,C6*Assumptions!$C$26+C7*Assumptions!$C$24+C8*Assumptions!$C$25) -> 1.5 | D33: =MAX(Assumptions!$C$29,D6*Assumptions!$C$26+D7*Assumptions!$C$24+D8*Assumptions!$C$25+(C9+C10)*Assumptions!$C$27+C11*Assumptions!$C$28) -> 1.5 | E33: =MAX(Assumptions!$C$29,E6*Assumptions!$C$26+E7*Assumptions!$C$24+E8*Assumptions!$C$25+(D9+D10)*Assumptions!$C$27+D11*Assumptions!$C$28) -> 1.75 | F33: =MAX(Assumptions!$C$29,F6*Assumptions!$C$26+F7*Assumptions!$C$24+F8*Assumptions!$C$25+(E9+E10)*Assumptions!$C$27+E11*Assumptions!$C$28) -> 2.35 | G33: =MAX(Assumptions!$C$29,G6*Assumptions!$C$26+G7*Assumptions!$C$24+G8*Assumptions!$C$25+(F9+F10)*Assumptions!$C$27+F11*Assumptions!$C$28) -> 3.2
A34: Core R&D / quant | C34: =Assumptions!C55 -> 3 | D34: =Assumptions!D55 -> 4 | E34: =Assumptions!E55 -> 5 | F34: =Assumptions!F55 -> 7 | G34: =Assumptions!G55 -> 9
A35: Sales | C35: =Assumptions!C56 -> 0.5 | D35: =Assumptions!D56 -> 1 | E35: =Assumptions!E56 -> 2 | F35: =Assumptions!F56 -> 2.5 | G35: =Assumptions!G56 -> 3
A36: Partner enablement | C36: =Assumptions!C57 -> 0 | D36: =Assumptions!D57 -> 0.5 | E36: =Assumptions!E57 -> 1.5 | F36: =Assumptions!F57 -> 2.5 | G36: =Assumptions!G57 -> 3.5
A37: G&A | C37: =Assumptions!C58 -> 0.5 | D37: =Assumptions!D58 -> 1 | E37: =Assumptions!E58 -> 1.5 | F37: =Assumptions!F58 -> 2 | G37: =Assumptions!G58 -> 3
A38: Total headcount | C38: =SUM(C33:C37) -> 5.5 | D38: =SUM(D33:D37) -> 8 | E38: =SUM(E33:E37) -> 11.75 | F38: =SUM(F33:F37) -> 16.35 | G38: =SUM(G33:G37) -> 21.7
A39: Costs and profit
A40: Personnel | C40: =C38*Assumptions!$C$37 -> 1.5125 | D40: =D38*Assumptions!$C$37 -> 2.2 | E40: =E38*Assumptions!$C$37 -> 3.23125 | F40: =F38*Assumptions!$C$37 -> 4.49625 | G40: =G38*Assumptions!$C$37 -> 5.9675
A41: Non-personnel | C41: =Assumptions!C59 -> 0.4 | D41: =Assumptions!D59 -> 0.55 | E41: =Assumptions!E59 -> 0.8 | F41: =Assumptions!F59 -> 1 | G41: =Assumptions!G59 -> 1.3
...

Sheet Valuation
A1: Valuation – Year 5 exit and implied value today
A2: Multiples are judgment for private vertical financial software, not sourced comparables. Edit blue cells.
C4: Low | D4: Mid | E4: High
A5: Multiple on recurring revenue | C5: 4 | D5: 6 | E5: 8
A6: Multiple on non-recurring revenue (license, services, M&A) | C6: 1 | D6: 1.5 | E6: 2
A7: Multiple on operating income (EBITDA cross-check) | C7: 10 | D7: 15 | E7: 20
A9: Year 5 inputs (from Model)
A10: Y5 total revenue | C10: =Model!G27 -> 13.36
A11: Y5 recurring revenue | C11: =Model!G28 -> 7.22
A12: Y5 non-recurring revenue | C12: =C10-C11 -> 6.14
A13: Y5 operating income | C13: =Model!G44 -> 5.4625
A15: Year 5 enterprise value ($M) | C15: Low | D15: Mid | E15: High
A16: Revenue-mix method | C16: =$C$11*C5+$C$12*C6 -> 35.02 | D16: =$C$11*D5+$C$12*D6 -> 52.53 | E16: =$C$11*E5+$C$12*E6 -> 70.04
A17: EBITDA method | C17: =MAX(0,$C$13)*C7 -> 54.625 | D17: =MAX(0,$C$13)*D7 -> 81.9375 | E17: =MAX(0,$C$13)*E7 -> 109.25
A18: Blended (average) | C18: =AVERAGE(C16:C17) -> 44.8225 | D18: =AVERAGE(D16:D17) -> 67.23375 | E18: =AVERAGE(E16:E17) -> 89.645
A19: Implied multiple of Y5 revenue | C19: =IFERROR(C18/$C$10,0) -> 3.3549775 | D19: =IFERROR(D18/$C$10,0) -> 5.0324663 | E19: =IFERROR(E18/$C$10,0) -> 6.7099551
A21: Implied value today (VC method)
A22: Target return multiple – pre-revenue (code + founders) | C22: 20
A23: Target return multiple – after 2 paid design partners | C23: 10
A24: Expected dilution before exit | C24: 0.15
C26: Low | D26: Mid | E26: High
A27: Post-money today – pre-revenue | C27: =C18*(1-$C$24)/$C$22 -> 1.9049562 | D27: =D18*(1-$C$24)/$C$22 -> 2.8574344 | E27: =E18*(1-$C$24)/$C$22 -> 3.8099125
A28: Post-money – after 2 paid design partners | C28: =C18*(1-$C$24)/$C$23 -> 3.8099125 | D28: =D18*(1-$C$24)/$C$23 -> 5.7148687 | E28: =E18*(1-$C$24)/$C$23 -> 7.619825
A30: Stage ladder (judgment)
A31: Pre-revenue: working code, synthetic data, no bank users | C31: Value set by team, domain depth and validation evidence; code alone is cheaper to replicate with coding agents
A32: 2 paid design partners, model-risk sign-off pending | C32: Re-price on proof that banks will validate and pay
A33: $3–5M recurring, 8–10 banks, first channel partner | C33: Recurring-revenue multiple starts to dominate
A34: Y5: $15–20M revenue, ~50% recurring, profitable | C34: Strategic buyers (ALM/risk vendors, core banking providers) or vertical-software PE
